Watching for file changes with StatReloader
Performing system checks...

System check identified some issues:

WARNINGS:
todos.Todo: (models.W042) Auto-created primary key used when not defining a primary key type, by default 'django.db.models.AutoField'.
	HINT: Configure the DEFAULT_AUTO_FIELD setting or the TodosConfig.default_auto_field attribute to point to a subclass of AutoField, e.g. 'django.db.models.BigAutoField'.

System check identified 1 issue (0 silenced).

You have 1 unapplied migration(s). Your project may not work properly until you apply the migrations for app(s): auth.
Run 'python manage.py migrate' to apply them.
February 26, 2023 - 23:00:29
Django version 4.1.7, using settings 'todoApp.settings'
Starting development server at http://0.0.0.0:8000/
Quit the server with CONTROL-C.
Watching for file changes with StatReloader
Performing system checks...

System check identified some issues:

WARNINGS:
todos.Todo: (models.W042) Auto-created primary key used when not defining a primary key type, by default 'django.db.models.AutoField'.
	HINT: Configure the DEFAULT_AUTO_FIELD setting or the TodosConfig.default_auto_field attribute to point to a subclass of AutoField, e.g. 'django.db.models.BigAutoField'.

System check identified 1 issue (0 silenced).

You have 1 unapplied migration(s). Your project may not work properly until you apply the migrations for app(s): auth.
Run 'python manage.py migrate' to apply them.
February 26, 2023 - 23:01:50
Django version 4.1.7, using settings 'todoApp.settings'
Starting development server at http://0.0.0.0:8000/
Quit the server with CONTROL-C.
Internal Server Error: /todos/add/
Traceback (most recent call last):
  File "/home/ubuntu/.local/lib/python3.10/site-packages/django/db/backends/utils.py", line 89, in _execute
    return self.cursor.execute(sql, params)
  File "/home/ubuntu/.local/lib/python3.10/site-packages/django/db/backends/sqlite3/base.py", line 357, in execute
    return Database.Cursor.execute(self, query, params)
sqlite3.OperationalError: attempt to write a readonly database

The above exception was the direct cause of the following exception:

Traceback (most recent call last):
  File "/home/ubuntu/.local/lib/python3.10/site-packages/django/core/handlers/exception.py", line 56, in inner
    response = get_response(request)
  File "/home/ubuntu/.local/lib/python3.10/site-packages/django/core/handlers/base.py", line 197, in _get_response
    response = wrapped_callback(request, *callback_args, **callback_kwargs)
  File "/home/ubuntu/projects/django-todo/todos/views.py", line 16, in add
    Todo.objects.create(title=title)
  File "/home/ubuntu/.local/lib/python3.10/site-packages/django/db/models/manager.py", line 85, in manager_method
    return getattr(self.get_queryset(), name)(*args, **kwargs)
  File "/home/ubuntu/.local/lib/python3.10/site-packages/django/db/models/query.py", line 671, in create
    obj.save(force_insert=True, using=self.db)
  File "/home/ubuntu/.local/lib/python3.10/site-packages/django/db/models/base.py", line 812, in save
    self.save_base(
  File "/home/ubuntu/.local/lib/python3.10/site-packages/django/db/models/base.py", line 863, in save_base
    updated = self._save_table(
  File "/home/ubuntu/.local/lib/python3.10/site-packages/django/db/models/base.py", line 1006, in _save_table
    results = self._do_insert(
  File "/home/ubuntu/.local/lib/python3.10/site-packages/django/db/models/base.py", line 1047, in _do_insert
    return manager._insert(
  File "/home/ubuntu/.local/lib/python3.10/site-packages/django/db/models/manager.py", line 85, in manager_method
    return getattr(self.get_queryset(), name)(*args, **kwargs)
  File "/home/ubuntu/.local/lib/python3.10/site-packages/django/db/models/query.py", line 1791, in _insert
    return query.get_compiler(using=using).execute_sql(returning_fields)
  File "/home/ubuntu/.local/lib/python3.10/site-packages/django/db/models/sql/compiler.py", line 1660, in execute_sql
    cursor.execute(sql, params)
  File "/home/ubuntu/.local/lib/python3.10/site-packages/django/db/backends/utils.py", line 102, in execute
    return super().execute(sql, params)
  File "/home/ubuntu/.local/lib/python3.10/site-packages/django/db/backends/utils.py", line 67, in execute
    return self._execute_with_wrappers(
  File "/home/ubuntu/.local/lib/python3.10/site-packages/django/db/backends/utils.py", line 80, in _execute_with_wrappers
    return executor(sql, params, many, context)
  File "/home/ubuntu/.local/lib/python3.10/site-packages/django/db/backends/utils.py", line 84, in _execute
    with self.db.wrap_database_errors:
  File "/home/ubuntu/.local/lib/python3.10/site-packages/django/db/utils.py", line 91, in __exit__
    raise dj_exc_value.with_traceback(traceback) from exc_value
  File "/home/ubuntu/.local/lib/python3.10/site-packages/django/db/backends/utils.py", line 89, in _execute
    return self.cursor.execute(sql, params)
  File "/home/ubuntu/.local/lib/python3.10/site-packages/django/db/backends/sqlite3/base.py", line 357, in execute
    return Database.Cursor.execute(self, query, params)
django.db.utils.OperationalError: attempt to write a readonly database
[26/Feb/2023 23:02:13] "POST /todos/add/ HTTP/1.1" 500 146423
